Workbook
Name ИменованныйДиапазон1: 'Матрица поставщиков'!$A$2:$A$100

Sheet Матрица продуктов
A1: Ингредиент | B1: Ед.изм. | C1: Вкусвилл | D1: Рынок-Бухта | E1: turkish-food
A2: Кориандр | B2: г | C2: =IFERROR(__xludf.DUMMYFUNCTION("IFERROR( FILTER( 'Матрица поставщиков'!E:E, 'Матрица поставщиков'!A:A = A2, 'Матрица поставщиков'!B:B = C1 ), 0 ) "),0.0) -> 0 | D2: =IFERROR(__xludf.DUMMYFUNCTION("IFERROR( FILTER( 'Матрица поставщиков'!E:E, 'Матрица поставщиков'!A:A = A2, 'Матрица поставщиков'!B:B = D1 ), 0 ) "),0.0) -> 0 | E2: =IFERROR(__xludf.DUMMYFUNCTION("IFERROR( FILTER( 'Матрица поставщиков'!E:E, 'Матрица поставщиков'!A:A = A2, 'Матрица поставщиков'!B:B = E1 ), 0 ) "),0.0) -> 0
A3: Корица | B3: г | C3: =IFERROR(__xludf.DUMMYFUNCTION("IFERROR( FILTER( 'Матрица поставщиков'!E:E, 'Матрица поставщиков'!A:A = A3, 'Матрица поставщиков'!B:B = C1 ), 0 ) "),0.0) -> 0 | D3: =IFERROR(__xludf.DUMMYFUNCTION("IFERROR( FILTER( 'Матрица поставщиков'!E:E, 'Матрица поставщиков'!A:A = A3, 'Матрица поставщиков'!B:B = D1 ), 0 ) "),0.0) -> 0 | E3: =IFERROR(__xludf.DUMMYFUNCTION("IFERROR( FILTER( 'Матрица поставщиков'!E:E, 'Матрица поставщиков'!A:A = A3, 'Матрица поставщиков'!B:B = E1 ), 0 ) "),0.0) -> 0
A4: Красный молотый перец | B4: г | C4: =IFERROR(__xludf.DUMMYFUNCTION("IFERROR( FILTER( 'Матрица поставщиков'!E:E, 'Матрица поставщиков'!A:A = A4, 'Матрица поставщиков'!B:B = C1 ), 0 ) "),0.0) -> 0 | D4: =IFERROR(__xludf.DUMMYFUNCTION("IFERROR( FILTER( 'Матрица поставщиков'!E:E, 'Матрица поставщиков'!A:A = A4, 'Матрица поставщиков'!B:B = D1 ), 0 ) "),0.0) -> 0 | E4: =IFERROR(__xludf.DUMMYFUNCTION("IFERROR( FILTER( 'Матрица поставщиков'!E:E, 'Матрица поставщиков'!A:A = A4, 'Матрица поставщиков'!B:B = E1 ), 0 ) "),0.0) -> 0
A5: Филе грудки куриное | B5: г | C5: =IFERROR(__xludf.DUMMYFUNCTION("IFERROR( FILTER( 'Матрица поставщиков'!E:E, 'Матрица поставщиков'!A:A = A5, 'Матрица поставщиков'!B:B = C1 ), 0 ) "),0.0) -> 0 | D5: =IFERROR(__xludf.DUMMYFUNCTION("IFERROR( FILTER( 'Матрица поставщиков'!E:E, 'Матрица поставщиков'!A:A = A5, 'Матрица поставщиков'!B:B = D1 ), 0 ) "),0.0) -> 0 | E5: =IFERROR(__xludf.DUMMYFUNCTION("IFERROR( FILTER( 'Матрица поставщиков'!E:E, 'Матрица поставщиков'!A:A = A5, 'Матрица поставщиков'!B:B = E1 ), 0 ) "),0.0) -> 0
A6: Бёдро без кости куриное | B6: г | C6: =IFERROR(__xludf.DUMMYFUNCTION("IFERROR( FILTER( 'Матрица поставщиков'!E:E, 'Матрица поставщиков'!A:A = A6, 'Матрица поставщиков'!B:B = C1 ), 0 ) "),0.0) -> 0 | D6: =IFERROR(__xludf.DUMMYFUNCTION("IFERROR( FILTER( 'Матрица поставщиков'!E:E, 'Матрица поставщиков'!A:A = A6, 'Матрица поставщиков'!B:B = D1 ), 0 ) "),0.0) -> 0 | E6: =IFERROR(__xludf.DUMMYFUNCTION("IFERROR( FILTER( 'Матрица поставщиков'!E:E, 'Матрица поставщиков'!A:A = A6, 'Матрица поставщиков'!B:B = E1 ), 0 ) "),0.0) -> 0
A7: Лимон | B7: г | C7: =IFERROR(__xludf.DUMMYFUNCTION("IFERROR( FILTER( 'Матрица поставщиков'!E:E, 'Матрица поставщиков'!A:A = A7, 'Матрица поставщиков'!B:B = C1 ), 0 ) "),0.0) -> 0 | D7: =IFERROR(__xludf.DUMMYFUNCTION("IFERROR( FILTER( 'Матрица поставщиков'!E:E, 'Матрица поставщиков'!A:A = A7, 'Матрица поставщиков'!B:B = D1 ), 0 ) "),0.0) -> 0 | E7: =IFERROR(__xludf.DUMMYFUNCTION("IFERROR( FILTER( 'Матрица поставщиков'!E:E, 'Матрица поставщиков'!A:A = A7, 'Матрица поставщиков'!B:B = E1 ), 0 ) "),0.0) -> 0
A8: ='Матрица поставщиков'!A9 -> Лук репчатый | B8: мл | C8: =IFERROR(__xludf.DUMMYFUNCTION("IFERROR( FILTER( 'Матрица поставщиков'!E:E, 'Матрица поставщиков'!A:A = A8, 'Матрица поставщиков'!B:B = C1 ), 0 ) "),0.0) -> 0 | D8: =IFERROR(__xludf.DUMMYFUNCTION("IFERROR( FILTER( 'Матрица поставщиков'!E:E, 'Матрица поставщиков'!A:A = A8, 'Матрица поставщиков'!B:B = D1 ), 0 ) "),0.0) -> 0 | E8: =IFERROR(__xludf.DUMMYFUNCTION("IFERROR( FILTER( 'Матрица поставщиков'!E:E, 'Матрица поставщиков'!A:A = A8, 'Матрица поставщиков'!B:B = E1 ), 0 ) "),0.0) -> 0
A9: Масло растительное | B9: мл | C9: =IFERROR(__xludf.DUMMYFUNCTION("IFERROR( FILTER( 'Матрица поставщиков'!E:E, 'Матрица поставщиков'!A:A = A9, 'Матрица поставщиков'!B:B = C1 ), 0 ) "),0.0) -> 0 | D9: =IFERROR(__xludf.DUMMYFUNCTION("IFERROR( FILTER( 'Матрица поставщиков'!E:E, 'Матрица поставщиков'!A:A = A9, 'Матрица поставщиков'!B:B = D1 ), 0 ) "),0.0) -> 0 | E9: =IFERROR(__xludf.DUMMYFUNCTION("IFERROR( FILTER( 'Матрица поставщиков'!E:E, 'Матрица поставщиков'!A:A = A9, 'Матрица поставщиков'!B:B = E1 ), 0 ) "),0.0) -> 0
A10: Оливковое масло | B10: мл | C10: =IFERROR(__xludf.DUMMYFUNCTION("IFERROR( FILTER( 'Матрица поставщиков'!E:E, 'Матрица поставщиков'!A:A = A10, 'Матрица поставщиков'!B:B = C1 ), 0 ) "),0.0) -> 0 | D10: =IFERROR(__xludf.DUMMYFUNCTION("IFERROR( FILTER( 'Матрица поставщиков'!E:E, 'Матрица поставщиков'!A:A = A10, 'Матрица поставщиков'!B:B = D1 ), 0 ) "),0.0) -> 0 | E10: =IFERROR(__xludf.DUMMYFUNCTION("IFERROR( FILTER( 'Матрица поставщиков'!E:E, 'Матрица поставщиков'!A:A = A10, 'Матрица поставщиков'!B:B = E1 ), 0 ) "),0.0) -> 0
A11: Сахар | B11: г | C11: =IFERROR(__xludf.DUMMYFUNCTION("IFERROR( FILTER( 'Матрица поставщиков'!E:E, 'Матрица поставщиков'!A:A = A11, 'Матрица поставщиков'!B:B = C1 ), 0 ) "),0.0) -> 0 | D11: =IFERROR(__xludf.DUMMYFUNCTION("IFERROR( FILTER( 'Матрица поставщиков'!E:E, 'Матрица поставщиков'!A:A = A11, 'Матрица поставщиков'!B:B = D1 ), 0 ) "),0.0) -> 0 | E11: =IFERROR(__xludf.DUMMYFUNCTION("IFERROR( FILTER( 'Матрица поставщиков'!E:E, 'Матрица поставщиков'!A:A = A11, 'Матрица поставщиков'!B:B = E1 ), 0 ) "),0.0) -> 0
A12: Сливочное масло | B12: г | C12: =IFERROR(__xludf.DUMMYFUNCTION("IFERROR( FILTER( 'Матрица поставщиков'!E:E, 'Матрица поставщиков'!A:A = A12, 'Матрица поставщиков'!B:B = C1 ), 0 ) "),0.0) -> 0 | D12: =IFERROR(__xludf.DUMMYFUNCTION("IFERROR( FILTER( 'Матрица поставщиков'!E:E, 'Матрица поставщиков'!A:A = A12, 'Матрица поставщиков'!B:B = D1 ), 0 ) "),0.0) -> 0 | E12: =IFERROR(__xludf.DUMMYFUNCTION("IFERROR( FILTER( 'Матрица поставщиков'!E:E, 'Матрица поставщиков'!A:A = A12, 'Матрица поставщиков'!B:B = E1 ), 0 ) "),0.0) -> 0
A13: Соль | B13: г | C13: =IFERROR(__xludf.DUMMYFUNCTION("IFERROR( FILTER( 'Матрица поставщиков'!E:E, 'Матрица поставщиков'!A:A = A13, 'Матрица поставщиков'!B:B = C1 ), 0 ) "),0.0) -> 0 | D13: =IFERROR(__xludf.DUMMYFUNCTION("IFERROR( FILTER( 'Матрица поставщиков'!E:E, 'Матрица поставщиков'!A:A = A13, 'Матрица поставщиков'!B:B = D1 ), 0 ) "),0.0) -> 0 | E13: =IFERROR(__xludf.DUMMYFUNCTION("IFERROR( FILTER( 'Матрица поставщиков'!E:E, 'Матрица поставщиков'!A:A = A13, 'Матрица поставщиков'!B:B = E1 ), 0 ) "),0.0) -> 0
A14: Сушёная мята | B14: г | C14: =IFERROR(__xludf.DUMMYFUNCTION("IFERROR( FILTER( 'Матрица поставщиков'!E:E, 'Матрица поставщиков'!A:A = A14, 'Матрица поставщиков'!B:B = C1 ), 0 ) "),0.0) -> 0 | D14: =IFERROR(__xludf.DUMMYFUNCTION("IFERROR( FILTER( 'Матрица поставщиков'!E:E, 'Матрица поставщиков'!A:A = A14, 'Матрица поставщиков'!B:B = D1 ), 0 ) "),0.0) -> 0 | E14: =IFERROR(__xludf.DUMMYFUNCTION("IFERROR( FILTER( 'Матрица поставщиков'!E:E, 'Матрица поставщиков'!A:A = A14, 'Матрица поставщиков'!B:B = E1 ), 0 ) "),0.0) -> 0
A15: Тимьян / Чабрец | B15: г | C15: =IFERROR(__xludf.DUMMYFUNCTION("IFERROR( FILTER( 'Матрица поставщиков'!E:E, 'Матрица поставщиков'!A:A = A15, 'Матрица поставщиков'!B:B = C1 ), 0 ) "),0.0) -> 0 | D15: =IFERROR(__xludf.DUMMYFUNCTION("IFERROR( FILTER( 'Матрица поставщиков'!E:E, 'Матрица поставщиков'!A:A = A15, 'Матрица поставщиков'!B:B = D1 ), 0 ) "),0.0) -> 0 | E15: =IFERROR(__xludf.DUMMYFUNCTION("IFERROR( FILTER( 'Матрица поставщиков'!E:E, 'Матрица поставщиков'!A:A = A15, 'Матрица поставщиков'!B:B = E1 ), 0 ) "),0.0) -> 0
A16: Тмин | B16: г | C16: =IFERROR(__xludf.DUMMYFUNCTION("IFERROR( FILTER( 'Матрица поставщиков'!E:E, 'Матрица поставщиков'!A:A = A16, 'Матрица поставщиков'!B:B = C1 ), 0 ) "),0.0) -> 0 | D16: =IFERROR(__xludf.DUMMYFUNCTION("IFERROR( FILTER( 'Матрица поставщиков'!E:E, 'Матрица поставщиков'!A:A = A16, 'Матрица поставщиков'!B:B = D1 ), 0 ) "),0.0) -> 0 | E16: =IFERROR(__xludf.DUMMYFUNCTION("IFERROR( FILTER( 'Матрица поставщиков'!E:E, 'Матрица поставщиков'!A:A = A16, 'Матрица поставщиков'!B:B = E1 ), 0 ) "),0.0) -> 0
A17: Томатная паста | B17: г | C17: =IFERROR(__xludf.DUMMYFUNCTION("IFERROR( FILTER( 'Матрица поставщиков'!E:E, 'Матрица поставщиков'!A:A = A17, 'Матрица поставщиков'!B:B = C1 ), 0 ) "),0.0) -> 0 | D17: =IFERROR(__xludf.DUMMYFUNCTION("IFERROR( FILTER( 'Матрица поставщиков'!E:E, 'Матрица поставщиков'!A:A = A17, 'Матрица поставщиков'!B:B = D1 ), 0 ) "),0.0) -> 0 | E17: =IFERROR(__xludf.DUMMYFUNCTION("IFERROR( FILTER( 'Матрица поставщиков'!E:E, 'Матрица поставщиков'!A:A = A17, 'Матрица поставщиков'!B:B = E1 ), 0 ) "),0.0) -> 0
A18: Чеснок | B18: г | C18: =IFERROR(__xludf.DUMMYFUNCTION("IFERROR( FILTER( 'Матрица поставщиков'!E:E, 'Матрица поставщиков'!A:A = A18, 'Матрица поставщиков'!B:B = C1 ), 0 ) "),0.0) -> 0 | D18: =IFERROR(__xludf.DUMMYFUNCTION("IFERROR( FILTER( 'Матрица поставщиков'!E:E, 'Матрица поставщиков'!A:A = A18, 'Матрица поставщиков'!B:B = D1 ), 0 ) "),0.0) -> 0 | E18: =IFERROR(__xludf.DUMMYFUNCTION("IFERROR( FILTER( 'Матрица поставщиков'!E:E, 'Матрица поставщиков'!A:A = A18, 'Матрица поставщиков'!B:B = E1 ), 0 ) "),0.0) -> 0
A19: Чёрный перец | B19: г | C19: =IFERROR(__xludf.DUMMYFUNCTION("IFERROR( FILTER( 'Матрица поставщиков'!E:E, 'Матрица поставщиков'!A:A = A19, 'Матрица поставщиков'!B:B = C1 ), 0 ) "),0.0) -> 0 | D19: =IFERROR(__xludf.DUMMYFUNCTION("IFERROR( FILTER( 'Матрица поставщиков'!E:E, 'Матрица поставщиков'!A:A = A19, 'Матрица поставщиков'!B:B = D1 ), 0 ) "),0.0) -> 0 | E19: =IFERROR(__xludf.DUMMYFUNCTION("IFERROR( FILTER( 'Матрица поставщиков'!E:E, 'Матрица поставщиков'!A:A = A19, 'Матрица поставщиков'!B:B = E1 ), 0 ) "),0.0) -> 0
A20: Маринованные огурцы (целые) | B20: г | C20: =IFERROR(__xludf.DUMMYFUNCTION("IFERROR( FILTER( 'Матрица поставщиков'!E:E, 'Матрица поставщиков'!A:A = A20, 'Матрица поставщиков'!B:B = C1 ), 0 ) "),0.0) -> 0 | D20: =IFERROR(__xludf.DUMMYFUNCTION("IFERROR( FILTER( 'Матрица поставщиков'!E:E, 'Матрица поставщиков'!A:A = A20, 'Матрица поставщиков'!B:B = D1 ), 0 ) "),0.0) -> 0 | E20: =IFERROR(__xludf.DUMMYFUNCTION("IFERROR( FILTER( 'Матрица поставщиков'!E:E, 'Матрица поставщиков'!A:A = A20, 'Матрица поставщиков'!B:B = E1 ), 0 ) "),0.0) -> 0
A21: Лаваш | B21: шт | C21: =IFERROR(__xludf.DUMMYFUNCTION("IFERROR( FILTER( 'Матрица поставщиков'!E:E, 'Матрица поставщиков'!A:A = A21, 'Матрица поставщиков'!B:B = C1 ), 0 ) "),0.0) -> 0 | D21: =IFERROR(__xludf.DUMMYFUNCTION("IFERROR( FILTER( 'Матрица поставщиков'!E:E, 'Матрица поставщиков'!A:A = A21, 'Матрица поставщиков'!B:B = D1 ), 0 ) "),0.0) -> 0 | E21: =IFERROR(__xludf.DUMMYFUNCTION("IFERROR( FILTER( 'Матрица поставщиков'!E:E, 'Матрица поставщиков'!A:A = A21, 'Матрица поставщиков'!B:B = E1 ), 0 ) "),0.0) -> 0
A22: Манная крупа | B22: г | C22: =IFERROR(__xludf.DUMMYFUNCTION("IFERROR( FILTER( 'Матрица поставщиков'!E:E, 'Матрица поставщиков'!A:A = A22, 'Матрица поставщиков'!B:B = C1 ), 0 ) "),0.0) -> 0 | D22: =IFERROR(__xludf.DUMMYFUNCTION("IFERROR( FILTER( 'Матрица поставщиков'!E:E, 'Матрица поставщиков'!A:A = A22, 'Матрица поставщиков'!B:B = D1 ), 0 ) "),0.0) -> 0 | E22: =IFERROR(__xludf.DUMMYFUNCTION("IFERROR( FILTER( 'Матрица поставщиков'!E:E, 'Матрица поставщиков'!A:A = A22, 'Матрица поставщиков'!B:B = E1 ), 0 ) "),0.0) -> 0
A23: Мука пшеничная (Французская штучка) | B23: г | C23: =IFERROR(__xludf.DUMMYFUNCTION("IFERROR( FILTER( 'Матрица поставщиков'!E:E, 'Матрица поставщиков'!A:A = A23, 'Матрица поставщиков'!B:B = C1 ), 0 ) "),0.0875) -> 0.0875 | D23: =IFERROR(__xludf.DUMMYFUNCTION("IFERROR( FILTER( 'Матрица поставщиков'!E:E, 'Матрица поставщиков'!A:A = A23, 'Матрица поставщиков'!B:B = D1 ), 0 ) "),0.0) -> 0 | E23: =IFERROR(__xludf.DUMMYFUNCTION("IFERROR( FILTER( 'Матрица поставщиков'!E:E, 'Матрица поставщиков'!A:A = A23, 'Матрица поставщиков'!B:B = E1 ), 0 ) "),0.0) -> 0
A24: Пекмез | B24: мл | C24: =IFERROR(__xludf.DUMMYFUNCTION("IFERROR( FILTER( 'Матрица поставщиков'!E:E, 'Матрица поставщиков'!A:A = A24, 'Матрица поставщиков'!B:B = C1 ), 0 ) "),0.0) -> 0 | D24: =IFERROR(__xludf.DUMMYFUNCTION("IFERROR( FILTER( 'Матрица поставщиков'!E:E, 'Матрица поставщиков'!A:A = A24, 'Матрица поставщиков'!B:B = D1 ), 0 ) "),0.0) -> 0 | E24: =IFERROR(__xludf.DUMMYFUNCTION("IFERROR( FILTER( 'Матрица поставщиков'!E:E, 'Матрица поставщиков'!A:A = A24, 'Матрица поставщиков'!B:B = E1 ), 0 ) "),1.0394736842105263) -> 1.0394737
A25: Арахис | B25: г | C25: =IFERROR(__xludf.DUMMYFUNCTION("IFERROR( FILTER( 'Матрица поставщиков'!E:E, 'Матрица поставщиков'!A:A = A25, 'Матрица поставщиков'!B:B = C1 ), 0 ) "),0.0) -> 0 | D25: =IFERROR(__xludf.DUMMYFUNCTION("IFERROR( FILTER( 'Матрица поставщиков'!E:E, 'Матрица поставщиков'!A:A = A25, 'Матрица поставщиков'!B:B = D1 ), 0 ) "),0.0) -> 0 | E25: =IFERROR(__xludf.DUMMYFUNCTION("IFERROR( FILTER( 'Матрица поставщиков'!E:E, 'Матрица поставщиков'!A:A = A25, 'Матрица поставщиков'!B:B = E1 ), 0 ) "),0.0) -> 0
A26: Молоко | B26: мл | C26: =IFERROR(__xludf.DUMMYFUNCTION("IFERROR( FILTER( 'Матрица поставщиков'!E:E, 'Матрица поставщиков'!A:A = A26, 'Матрица поставщиков'!B:B = C1 ), 0 ) "),0.0) -> 0 | D26: =IFERROR(__xludf.DUMMYFUNCTION("IFERROR( FILTER( 'Матрица поставщиков'!E:E, 'Матрица поставщиков'!A:A = A26, 'Матрица поставщиков'!B:B = D1 ), 0 ) "),0.0) -> 0 | E26: =IFERROR(__xludf.DUMMYFUNCTION("IFERROR( FILTER( 'Матрица поставщиков'!E:E, 'Матрица поставщиков'!A:A = A26, 'Матрица поставщиков'!B:B = E1 ), 0 ) "),0.0) -> 0
A27: Мороженое пломбир | B27: г | C27: =IFERROR(__xludf.DUMMYFUNCTION("IFERROR( FILTER( 'Матрица поставщиков'!E:E, 'Матрица поставщиков'!A:A = A27, 'Матрица поставщиков'!B:B = C1 ), 0 ) "),0.0) -> 0 | D27: =IFERROR(__xludf.DUMMYFUNCTION("IFERROR( FILTER( 'Матрица поставщиков'!E:E, 'Матрица поставщиков'!A:A = A27, 'Матрица поставщиков'!B:B = D1 ), 0 ) "),0.0) -> 0 | E27: =IFERROR(__xludf.DUMMYFUNCTION("IFERROR( FILTER( 'Матрица поставщиков'!E:E, 'Матрица поставщиков'!A:A = A27, 'Матрица поставщиков'!B:B = E1 ), 0 ) "),0.0) -> 0
A28: Тахин | B28: мл | C28: =IFERROR(__xludf.DUMMYFUNCTION("IFERROR( FILTER( 'Матрица поставщиков'!E:E, 'Матрица поставщиков'!A:A = A28, 'Матрица поставщиков'!B:B = C2 ), 0 ) "),0.0) -> 0 | D28: =IFERROR(__xludf.DUMMYFUNCTION("IFERROR( FILTER( 'Матрица поставщиков'!E:E, 'Матрица поставщиков'!A:A = A28, 'Матрица поставщиков'!B:B = D1 ), 0 ) "),0.0) -> 0 | E28: =IFERROR(__xludf.DUMMYFUNCTION("IFERROR( FILTER( 'Матрица поставщиков'!E:E, 'Матрица поставщиков'!A:A = A28, 'Матрица поставщиков'!B:B = E1 ), 0 ) "),1.3727272727272728) -> 1.3727273
A29: Йогурт | B29: г

Sheet Матрица поставщиков
A1: Ингредиент | B1: Поставщик | C1: Вес/Объем упаковки | D1: Стоимость упаковки | E1: Стоимость за 1 ед. изм. | F1: Дата проценки
A2: вода | B2: METRO | C2: 5000 | D2: 0 | E2: =D2/C2 -> 0 | F2: 46048 | J2: вход | K2: продукты | L2: цена филе бкбк | M2: цена филе грудки | Q2: вытяжка
A3: кориандр | B3: METRO | C3: 320 | D3: 398 | E3: =D3/C3 -> 1.24375 | F3: 45663 | J3: № тел | K3: https://b2b.lenta.com | L3: 480 | M3: 458 | Q3: https://psk-pro.ru
A4: корица | B4: METRO | C4: 100 | D4: 134 | E4: =D4/C4 -> 1.34 | F4: 45663 | J4: urazovildar@yandex.ru / axel33 | K4: https://napolke.ru | L4: 380 | M4: 369 | Q4: https://www.ventsistema.ru/uslugi/proektirovanie-system-ventilyacii-restoran-kafe
A5: Красный молотый перец | B5: METRO | C5: 365 | D5: 609 | E5: =D5/C5 -> 1.6684932 | F5: 45663 | J5: заявка отправлена | K5: www.ews.ru/ | N5: callcenter@ews.ru | Q5: https://ceds.ru/inzhenernye-sistemy/ventilyatsiya/ventilyatsiya-restoranov-kafe-i-barov
A6: Филе грудки куриное | B6: METRO | C6: 1000 | D6: 339 | E6: =D6/C6 -> 0.339 | F6: 45663 | G6: от 0 до +2С | H6: 10 дн? | J6: заявка отправлена | K6: https://www.abri-kos.ru | L6: 502 | M6: 441 | N6: с/м | Q6: https://psk-pro.ru
A7: Бёдро без кости куриное | B7: METRO | C7: 1000 | D7: 389 | E7: =D7/C7 -> 0.389 | F7: 45663 | G7: от 0 до +2С | H7: 10 дн? | J7: заявка отправлена | K7: https://marr.ru | Q7: https://ventell.ru/ventilyatsiya-pomescheniy/ventilyatsiya-obschepita
A8: Лимон | B8: METRO | C8: 1000 | D8: 259 | E8: =D8/C8 -> 0.259 | F8: 45663 | J8: Axel33 | K8: https://gfc-russia.ru/?version=2 | L8: 459 | M8: 421 | N8: зам | Q8: https://regul-vent.ru/page/montazh-ventilyatsii-dlya-predpriyatiy-obschestvennogo-pitaniya#2
A9: Лук репчатый | B9: METRO | C9: 1000 | D9: 57 | E9: =D9/C9 -> 0.057 | F9: 46051 | J9: заявка отправлена | K9: https://cherri.msk.ru | Q9: https://mosecoclean.ru/montazh-ventilyatsii-v-restorane
A10: Масло растительное | B10: METRO | C10: 5000 | D10: 609 | E10: =D10/C10 -> 0.1218 | F10: 46101 | G10: от 0 до +25С | H10: 365 дн | J10: заявка отправлена | K10: https://beriozkafood.ru | Q10: https://pskaksioma.ru/ventilyacziya-restoranov-kafe-i-barov
A11: Уксус яблочный | B11: METRO | C11: 250 | D11: 58 | E11: =D11/C11 -> 0.232 | F11: 45663 | J11: заявка отправлена | K11: https://fudstori.ru | Q11: https://www.avito.ru/moskva/predlozheniya_uslug/proektirovanie_i_montazh_sistem_ventilyatsii_2244962269?context=H4sIAAAAAAAA_wE_AMD_YToyOntzOjEzOiJsb2NhbFByaW9yaXR5IjtiOjE7czoxOiJ4IjtzOjE2OiJxbVh4cVBqYVhjbjdldnVMIjt9U6a5OT8AAAA
A12: Сахар | B12: METRO | C12: 1000 | D12: 69 | E12: =D12/C12 -> 0.069 | F12: 45663 | J12: заявка отправлена | K12: https://arosa.ru
A13: Сливочное масло | B13: METRO | C13: 450 | D13: 449 | E13: =D13/C13 -> 0.99777778 | F13: 46101 | J13: urazovildar@yandex.ru / Rakwl9rT | K13: https://vkusvill.ru/b2b | L13: 597 | M13: 583
A14: Соль | B14: METRO | C14: 1000 | D14: 42 | E14: =D14/C14 -> 0.042 | F14: 45663 | J14: заявка отправлена | K14: https://rosinterfood.ru
A15: Сушёная мята | B15: METRO | C15: 60 | D15: 113 | E15: =D15/C15 -> 1.8833333 | F15: 45663 | K15: https://azbuka-produktov.ru
A16: Тимьян / Чабрец | B16: озон | C16: 500 | D16: 414 | E16: =D16/C16 -> 0.828 | F16: 45663 | J16: заявка отправлена | K16: https://ice-m.com | L16: 300 | M16: 300 | N16: скорее всего з/м
A17: Тмин | B17: METRO | C17: 490 | D17: 596 | E17: =D17/C17 -> 1.2163265 | F17: 45663 | J17: заявка отправлена | K17: https://swlife.ru | L17: 430 | M17: 410 | N17: охл
A18: Томатная паста | B18: Вагиф | C18: 5000 | D18: 515 | E18: =D18/C18 -> 0.103 | F18: 45663 | G18: 4±2°С. | H18: 3 года | J18: заявка отправлена | K18: https://opttorg-horeca.ru | N18: фудсити
A19: Чеснок | B19: METRO | C19: 1000 | D19: 216 | E19: =D19/C19 -> 0.216 | F19: 45663 | J19: заявка отправлена | K19: https://fydopt.ru | N19: 9091694849 Оксана | O19: мерк чз всё есть
A20: Чёрный перец | B20: METRO | C20: 1000 | D20: 1057 | E20: =D20/C20 -> 1.057 | F20: 45663 | J20: заявка отправлена | K20: https://grossfood.ru
A21: Лаваш | B21: https://moslavash.ru | C21: 1 | D21: 9.5 | E21: 14.5 | F21: 45672 | G21: цена при заказе 100шт доставкой | H21: 5 суток | J21: заявка отправлена | K21: https://food-fresh.ru
A22: Петрушка | B22: METRO | C22: 90 | D22: 280 | E22: =D22/C22 -> 3.1111111 | F22: 45663 | J22: заявка отправлена | K22: https://fk-frutcity.ru
A23: Помидоры - сливовые | B23: METRO | C23: 1000 | D23: 350 | E23: =D23/C23 -> 0.35 | F23: 46101 | G23: от +2 до +8С
A24: Маринованные огурцы (целые) | B24: METRO | C24: 1500 | D24: 547 | E24: =D24/C24 -> 0.36466667 | F24: 46101
A25: копченая паприка 1 | B25: OZON | C25: 1000 | D25: 700 | E25: =D25/C25 -> 0.7 | F25: 45663
A26: Кетчуп Heinz | B26: METRO | C26: 800 | D26: 223 | E26: =D26/C26 -> 0.27875 | F26: 45663
A27: Мука | B27: METRO | C27: 2000 | D27: 76 | E27: =D27/C27 -> 0.038 | F27: 45663
A28: Манная крупа | B28: METRO | C28: 800 | D28: 69 | E28: =D28/C28 -> 0.08625 | F28: 46050
A29: Ванилин | B29: METRO | C29: 200 | D29: 460 | E29: =D29/C29 -> 2.3 | F29: 45663
A30: Тахин | B30: turkish-food | C30: 550 | D30: 755 | E30: =D30/C30 -> 1.3727273
A31: Чеддер плавленный | B31: METRO | C31: 150 | D31: 130 | E31: =D31/C31 -> 0.86666667 | F31: 45663 | G31: Hochland чизбургер | K31: упаковка
A32: Мука пшеничная (Французская штучка) | B32: Вкусвилл | C32: 2000 | D32: 175 | E32: =D32/C32 -> 0.0875 | K32: https://1ea.ru
A33: Пекмез | B33: turkish-food | C33: 380 | D33: 395 | E33: =D33/C33 -> 1.0394737 | K33: https://severupack.ru
A34: Арахис | B34: METRO | C34: 800 | D34: 340 | E34: =D34/C34 -> 0.425 | F34: 45663
A35: Молоко | B35: METRO | C35: 1000 | D35: 60 | E35: =D35/C35 -> 0.06 | F35: 45663
A36: Йогурт турецкий | B36: METRO | C36: 1000 | D36: 289 | E36: =D36/C36 -> 0.289 | F36: 45663 | G36: от 2С до 4С | H36: 3 суток
A37: Паприка | B37: METRO | C37: 1000 | D37: 670 | E37: =D37/C37 -> 0.67 | F37: 45663
A38: Сухой чеснок | B38: METRO | C38: 440 | D38: 590 | E38: =D38/C38 -> 1.3409091 | F38: 45663
A39: Лимонный сок | B39: METRO | C39: 1000 | D39: 284 | E39: =D39/C39 -> 0.284 | F39: 45663
A40: Фарш Primebeef Классик говяжий охлажденный | B40: METRO | C40: 2000 | D40: 1679 | E40: =D40/C40 -> 0.8395 | F40: 46048
...

Sheet Сводная
A1: Категория | B1: Наименование | C1: цена | D1: цена в доставке | E1: cost финальный | F1: cost продуктов | G1: выход | H1: с/с продуктов | I1: с/с списания | J1: с/с упаковка | K1: с/с общая
A2: Дюрюмы
B3: ='Дюрюм'!B1 -> #REF! | C3: ='Дюрюм'!B33 -> #REF! | D3: ='Дюрюм'!B35 -> #REF! | E3: ='Дюрюм'!B30 -> #REF! | F3: ='Дюрюм'!B32 -> #REF! | G3: ='Дюрюм'!I11 -> #REF! | H3: ='Дюрюм'!C18 -> #REF! | I3: ='Дюрюм'!C19 -> #REF! | J3: ='Дюрюм'!C24 -> #REF! | K3: ='Дюрюм'!C28 -> #REF!
B4: ='Искандер дюрюм Zurna'!B1 -> Iskendy Durum Zurna | C4: ='Искандер дюрюм Zurna'!B30 -> 800 | D4: ='Искандер дюрюм Zurna'!B36 -> 1150 | E4: ='Искандер дюрюм Zurna'!B31 -> 0.22637143 | F4: ='Искандер дюрюм Zurna'!B32 -> 0.20554018 | G4: ='Искандер дюрюм Zurna'!I11 -> 721 | H4: ='Искандер дюрюм Zurna'!C18 -> 164.43214 | I4: ='Искандер дюрюм Zurna'!C19 -> 6.5772858 | J4: ='Искандер дюрюм Zurna'!C20 -> 1.2 | K4: ='Искандер дюрюм Zurna'!C25 -> 172.20943
A5: Напитки
B6: ='Чай чёрный'!B1 -> Чай чёрный | C6: ='Чай чёрный'!C21 -> 150 | E6: ='Чай чёрный'!C22 -> 0.054998222 | F6: ='Чай чёрный'!C23 -> 0.0080111111 | G6: ='Чай чёрный'!I6 -> 4800 | H6: ='Чай чёрный'!D16 -> 1.2016667 | I6: ='Чай чёрный'!D17 -> 0.048066667 | J6: ='Чай чёрный'!D18 -> 7 | K6: ='Чай чёрный'!D19 -> 8.2497333
B7: Айран | C7: ='Айран'!C23 -> 190 | D7: ='Айран'!D23 -> 271.42857 | E7: ='Айран'!C24 -> 0.22105263 | G7: ='Айран'!F5 -> 270
B8: ='Кофе по-турецки'!B1 -> Кофе по-турецки | C8: ='Кофе по-турецки'!C23 -> 250 | E8: ='Кофе по-турецки'!C24 -> 0.1152864 | F8: ='Кофе по-турецки'!C25 -> 0.10316 | G8: ='Кофе по-турецки'!I8 -> 100 | H8: ='Кофе по-турецки'!D18 -> 25.79 | I8: ='Чай чёрный'!D17 -> 0.048066667 | J8: ='Кофе по-турецки'!D20 -> 2 | K8: ='Кофе по-турецки'!D21 -> 28.8216
B9: ='Кофе по-турецки с кардамоном'!B1 -> Кофе по-турецки с кардамоном | C9: ='Кофе по-турецки с кардамоном'!C22 -> 240 | E9: ='Кофе по-турецки с кардамоном'!C23 -> #N/A | F9: ='Кофе по-турецки с кардамоном'!C24 -> #N/A | G9: ='Кофе по-турецки с кардамоном'!I7 -> 100 | H9: ='Кофе по-турецки с кардамоном'!D17 -> #N/A | I9: ='Кофе по-турецки с кардамоном'!D18 -> #N/A | J9: ='Кофе по-турецки с кардамоном'!D19 -> 4 | K9: ='Кофе по-турецки с кардамоном'!D20 -> #N/A
B10: ='Кофе по-турецки с фундуком'!B1 -> Кофе по-турецки с фундуком | C10: ='Кофе по-турецки с фундуком'!C21 -> 350 | E10: ='Кофе по-турецки с фундуком'!C22 -> 0.13028571 | F10: ='Кофе по-турецки с фундуком'!C23 -> 0.11428571 | G10: ='Кофе по-турецки с фундуком'!I6 -> 110 | H10: ='Кофе по-турецки с фундуком'!D16 -> 40 | I10: ='Кофе по-турецки с фундуком'!D17 -> 1.6 | J10: ='Кофе по-турецки с фундуком'!D18 -> 4 | K10: ='Кофе по-турецки с фундуком'!D19 -> 45.6
B11: Лимонад | C11: ='Лимонад'!C28 -> 200 | E11: ='Лимонад'!C29 -> 0.1896075 | F11: ='Лимонад'!C30 -> 0.14525 | G11: ='Лимонад'!I9 -> 365 | H11: ='Лимонад'!D23 -> 29.05 | I11: ='Лимонад'!D24 -> 0.8715 | J11: ='Лимонад'!D25 -> 8 | K11: ='Лимонад'!D26 -> 37.9215
B12: ='Айран коктейль'!B1 -> Айран коктейль | C12: ='Айран коктейль'!C25 -> 290 | E12: ='Айран коктейль'!C26 -> 0.25275862 | F12: ='Айран коктейль'!C27 -> 0.21982759 | G12: ='Айран коктейль'!I9 -> 365 | H12: ='Айран коктейль'!D20 -> 63.75 | I12: ='Айран коктейль'!D21 -> 2.55 | J12: ='Айран коктейль'!D22 -> 7 | K12: ='Айран коктейль'!D23 -> 73.3
A13: Фингерфуд
B14: ='Фри на продажу'!B1 -> Фри | C14: ='Фри на продажу'!C33 -> 230 | D14: ='Фри на продажу'!C39 -> 330 | E14: ='Фри на продажу'!C34 -> 0.19005646 | F14: ='Фри на продажу'!C35 -> 0.14544776 | G14: ='Фри на продажу'!I8 -> 100 | H14: ='Фри на продажу'!D18 -> 33.452985 | I14: ='Фри на продажу'!D19 -> 2 | J14: ='Фри на продажу'!D20 -> 1.2 | K14: ='Фри на продажу'!D26 -> 45.972985
A15: Суп
B16: ='Чечевичный суп'!B1 -> Чечевичный суп | C16: ='Чечевичный суп'!B24 -> 300 | D16: ='Чечевичный суп'!B27 -> 430 | E16: ='Чечевичный суп'!B22 -> 0.14035644
A17: Extra
B18: ='Сырный соус'!B1 -> Сырный соус | C18: ='Сырный соус'!C30 -> 70 | D18: ='Сырный соус'!C36 -> 100 | E18: ='Сырный соус'!C31 -> 0.28898571 | F18: ='Сырный соус'!C32 -> 0.22098571 | G18: ='Сырный соус'!I5 -> 30 | H18: ='Сырный соус'!C10 -> 15.469 | I18: ='Сырный соус'!D16 | J18: ='Сырный соус'!J31 -> 4.76 | K18: ='Сырный соус'!J33 -> 20.229
B19: ='Перец Якан'!B1 -> Перец Якан | C19: ='Перец Якан'!C30 -> 60 | D19: ='Перец Якан'!C36 -> 85 | E19: ='Перец Якан'!C31 -> 0.17246667
B20: ='Кетчуп'!B1 -> Кетчуп | C20: ='Кетчуп'!C30 -> 70 | D20: ='Кетчуп'!C36 -> 100 | E20: ='Кетчуп'!C31 -> 0.19144643 | F20: ='Кетчуп'!C32 -> 0.12344643 | G20: ='Кетчуп'!I5 -> 30 | H20: ='Кетчуп'!G5 -> 8.64125 | J20: ='Кетчуп'!I38 -> 4.76 | K20: ='Кетчуп'!I39 -> 13.40125
A21: Десерты
B22: ='Манная халва'!B1 -> Манная халва | C22: ='Манная халва'!C20 -> 250 | D22: ='Манная халва'!C25 -> 350 | E22: ='Манная халва'!C21 -> 0.20394327 | F22: ='Манная халва'!C22 -> 0.10970327 | G22: ='Манная халва'!B10 -> 150 | H22: ='Манная халва'!C10 -> 27.425819 | I22: ='Манная халва'!G19 -> 2 | J22: ='Манная халва'!D16 -> 23.56 | K22: ='Манная халва'!D17 -> 50.985819
B23: ='Манная халва с шоко'!B1 -> Манная халва с шоколадом | C23: ='Манная халва с шоко'!C21 -> 300 | D23: ='Манная халва с шоко'!C26 -> 430 | E23: ='Манная халва с шоко'!C22 -> 0.1936693 | F23: ='Манная халва с шоко'!C23 -> 0.11513596 | G23: ='Манная халва с шоко'!I6 -> 180 | H23: ='Манная халва с шоко'!D16 -> 34.540789 | I23: ='Манная халва с шоко'!D17 -> 0 | J23: ='Манная халва с шоко'!D18 -> 23.56 | K23: ='Манная халва с шоко'!C11 -> 34.540789
A24: Кмобо
B25: ='Комбо-1_1'!B1 -> Комбо: Дюрюм + фри + соус + напиток | C25: ='Комбо-1_1'!G8 -> 850 | D25: ='Комбо-1_1'!G10 -> 1360 | E25: ='Комбо-1_1'!L8 -> #REF! | G25: ='Комбо-1_1'!B8 -> 480 | H25: ='Комбо-1_1'!D8 -> #REF! | J25: ='Комбо-1_1'!D7 -> 52 | K25: ='Комбо-1_1'!D8 -> #REF!
B26: ='Комбо-1_2'!B1 -> Комбо: Дюрюм + суп +фри + соус + напиток | C26: ='Комбо-1_2'!H9 -> 950 | D26: ='Комбо-1_2'!H11 -> 1360 | E26: ='Комбо-1_2'!L9 -> #REF! | G26: ='Комбо-1_2'!B9 -> 950 | H26: ='Комбо-1_2'!E9 -> #REF! | K26: ='Комбо-1_2'!E9 -> #REF!

Sheet Доставка
A1: Название | B1: % | D1: Коэффициент надбавки
A2: Комиссия яндекса | B2: 30
A3: стоимость доставки в заказе в долях
A4: Итого | B4: =sum(B2:B3) -> 30

Sheet Сырный соус
A1: Наименование ТТК: | B1: Сырный соус
A3: Ингредиент | B3: Брутто | C3: Нетто | D3: Ед.изм. | E3: вес потери | F3: % потери | G3: с/с руб. | H3: с/с % | I3: Выход (мл.)
A4: Сырный соус Heinz | B4: 31 | C4: 30 | D4: г. | E4: =B4-C4 -> 1 | F4: =E4/B4*100 -> 3.2258065 | G4: =VLOOKUP(A4,'Матрица поставщиков'!A1:E530,5,0) * B4 -> 15.469 | H4: =G4/G5 -> 1
A5: Итого | B5: =SUM(B4) -> 31 | C5: =SUM(C4) -> 30 | D5: г. | E5: =B5-C5 -> 1 | F5: =E5/B5*100 -> 3.2258065 | G5: =SUM(G4) -> 15.469 | H5: =SUM(H4) -> 1 | I5: =B5-E5 -> 30
A7: Технология приготовления
A8: Добавить в соусник 30гр соуса
B9: выход | C9: с/с
B10: =I5 -> 30 | C10: =G5/I5*B10 -> 15.469
B11: 1 | C11: =G5/I5*B11 -> 0.51563333
B13: Для расчёта цены продажи
C14: % | D14: руб | E14: цена так
F15: cost (%) | G15: 10 | H15: 15 | I15: 20
F16: price | G16: =D23*100/G15 -> 0 | H16: =D23*100/H15 -> 0 | I16: =D23*100/I15 -> 0
H21: на месте | I21: с собой | J21: доставка
G22: списания | H22: 0 | I22: 0 | J22: 0
G23: салфетки 4 шт. | H23: 0 | I23: 0 | J23: 0
G24: зубочистка | H24: 0 | I24: 0 | J24: 0
G25: пакет | H25: 0 | I25: 0 | J25: 0
G26: наклейка брендированная | H26: 2.5 | I26: 2.5 | J26: 2.5
G27: Соусник | H27: 2.26 | I27: 2.26 | J27: 2.26
G28: Крышка | H28: 0 | I28: 0 | J28: 0
B30: цена | C30: 70 | D30: =C30+J31 -> 74.76
B31: cost общий | C31: =J33/C30 -> 0.28898571 | G31: упаковка | H31: =SUM(H22:H30) -> 4.76 | I31: =SUM(I22:I30) -> 4.76 | J31: =SUM(J22:J30) -> 4.76
B32: cost - продукции | C32: =G5/C30 -> 0.22098571
G33: с/с общий | J33: =G5+J31 -> 20.229
B35: цена | C35: 70
B36: доставка | C36: 100

Sheet Кетчуп
A1: Наименование ТТК: | B1: Кетчуп
A3: Ингредиент | B3: Брутто | C3: Нетто | D3: Ед.изм. | E3: вес потери | F3: % потери | G3: с/с руб. | H3: с/с % | I3: Выход (мл.)
A4: Кетчуп Heinz | B4: 31 | C4: 30 | D4: г. | E4: =B4-C4 -> 1 | F4: =E4/B4*100 -> 3.2258065 | G4: =VLOOKUP(A4,'Матрица поставщиков'!A1:E530,5,0) * B4 -> 8.64125 | H4: =G4/G5 -> 1
A5: Итого | B5: =SUM(B4) -> 31 | C5: =SUM(C4) -> 30 | D5: г. | E5: =B5-C5 -> 1 | F5: =E5/B5*100 -> 3.2258065 | G5: =SUM(G4) -> 8.64125 | H5: =SUM(H4) -> 1 | I5: =B5-E5 -> 30
A7: Технология приготовления
A8: Добавить в соусник 30гр соуса
B9: выход | C9: с/с
B10: =I5 -> 30 | C10: =G5/I5*B10 -> 8.64125
B11: 1 | C11: =G5/I5*B11 -> 0.28804167
B13: Для расчёта цены продажи
C14: % | D14: руб | E14: цена так
F15: cost (%) | G15: 10 | H15: 15 | I15: 20
F16: price | G16: =D23*100/G15 -> 0 | H16: =D23*100/H15 -> 0 | I16: =D23*100/I15 -> 0
B30: цена | C30: 70 | D30: =C30+I38 -> 74.76 | G30: на месте | H30: с собой | I30: доставка
B31: cost общий | C31: =I39/C30 -> 0.19144643 | F31: списания | G31: 0 | H31: 0 | I31: 0
B32: cost - продукции | C32: =G5/C30 -> 0.12344643 | F32: салфетки 4 шт. | G32: 0 | H32: 0 | I32: 0
F33: зубочистка | G33: 0 | H33: 0 | I33: 0
F34: пакет | G34: 0 | H34: 0 | I34: 0
B35: цена | C35: 70 | F35: наклейка брендированная | G35: 2.5 | H35: 2.5 | I35: 2.5
B36: доставка | C36: 100 | F36: Соусник | G36: 2.26 | H36: 2.26 | I36: 2.26
F37: Крышка | G37: 0 | H37: 0 | I37: 0
F38: упаковка | G38: =SUM(G31:G37) -> 4.76 | H38: =SUM(H31:H37) -> 4.76 | I38: =SUM(I31:I37) -> 4.76
F39: с/с общая | I39: =G5+I38 -> 13.40125

Sheet Лимонад
A1: Наименование ТТК: | B1: Чай чёрный
K2: Вкусы
A3: Ингредиент | B3: Брутто | C3: Нетто | D3: Ед.изм. | E3: вес потери | F3: % потери | G3: с/с руб. | H3: с/с % | I3: Выход (мл.) | K3: База | L3: Акцент
A4: Вода газированная | B4: 150 | C4: =B4 -> 150 | D4: мл. | E4: =B4-C4 -> 0 | F4: =E4/B4*100 -> 0 | G4: =VLOOKUP(A4,'Матрица поставщиков'!A1:E60,5,False) * B4 -> 4.35 | H4: =G4/G9 -> 0.14974182 | K4: Арбуз | L4: Айва
A5: Концентрат сока | B5: 25 | C5: =B5 -> 25 | D5: мл. | E5: =B5-C5 -> 0 | F5: =E5/B5*100 -> 0 | G5: =VLOOKUP(A5,'Матрица поставщиков'!A1:E100,5,False) * B5 -> 10 | H5: =G5/$G$9 -> 0.34423408 | K5: Гранат | L5: Яблоко
A6: Концентрат сока | B6: 20 | C6: =B6 -> 20 | D6: мл. | E6: =B6-C6 -> 0 | F6: =E6/B6*100 -> 0 | G6: =VLOOKUP(A6,'Матрица поставщиков'!A2:E101,5,False) * B6 -> 8 | H6: =G6/$G$9 -> 0.27538726 | K6: Кизил | L6: Лимон
A7: Сахарный сироп | B7: 20 | C7: 20 | D7: мл. | E7: =B7-C7 -> 0 | F7: =E7/B7*100 -> 0 | G7: =VLOOKUP(A7,'Матрица поставщиков'!A3:E62,5,False) * B7 -> 6.7 | H7: =G7/$G$9 -> 0.23063683 | K7: Виноград | L7: Розовая вода
A8: Лёд куб | B8: 150 | C8: 150 | D8: мл. | E8: =B8-C8 -> 0 | F8: =E8/B8*100 -> 0 | G8: =VLOOKUP(A8,'Матрица поставщиков'!A4:E62,5,False) * B8 -> 0 | H8: =G8/$G$9 -> 0 | K8: Клубника | L8: Розмарин
A9: Итого | B9: =SUM(B4:B8) -> 365 | C9: =SUM(C3:C8) -> 365 | D9: - | E9: =B9-C9 -> 0 | F9: =E9/B9*100 -> 0 | G9: =SUM(G4:G8) -> 29.05 | H9: =SUM(H4:H8) -> 1 | I9: =B9-E9 -> 365
A11: Технология приготовления
A12: 1. Смешать газированную воду, концентрат сока, сахарный сиор, лёд
B17: Для расчёта цены продажи
B18: выход | C18: с/с | E18: cost (%) | F18: 10 | G18: 15 | H18: 20
B19: =B9 -> 365 | C19: =G9/I9*B19 -> 29.05 | E19: price | F19: =D26*100/F18 -> 379.215 | G19: =D26*100/G18 -> 252.81 | H19: =D26*100/H18 -> 189.6075
B20: 1 | C20: =G9/I9*B20 -> 0.079589041
C22: % | D22: руб
B23: с/с блюда | C23: =D23/D26 -> 0.76605619 | D23: =C19 -> 29.05
B24: списания | C24: 0.03 | D24: =D23*C24 -> 0.8715
B25: упаковка | C25: =D25/D26 -> 0.21096212 | D25: 8
B26: Итого с/с | D26: =SUM(D23:D25) -> 37.9215
B28: цена | C28: 200
B29: cost общий | C29: =D26/C28 -> 0.1896075
B30: cost - продукции | C30: =D23/C28 -> 0.14525

Sheet Айран
A1: Наименование ТТК: | B1: Айран
A3: Ингредиент | B3: Брутто | C3: Ед.изм. | D3: с/с руб. | E3: с/с % | F3: Выход (мл.)
A4: Айран 2% | B4: 270 | C4: г. | D4: =VLOOKUP(A4,'Матрица поставщиков'!A1:E100,5,0) * B4 -> 42 | E4: =D4/D5 -> 1 | F4: =B5 -> 270
A5: Итого | B5: =B4 -> 270 | C5: - | D5: =SUM(D4) -> 42 | E5: =SUM(E4) -> 1 | F5: =SUM(F4) -> 270
B9: выход | C9: с/с
B10: =B5 -> 270 | C10: =D5 -> 42
B11: 1 | C11: =C10/250 -> 0.168
B13: Для расчёта цены продажи
C14: % | D14: руб | E14: цена так
B15: с/с блюда | C15: =D15/D18 -> 1 | D15: =C10 -> 42 | F15: cost (%) | G15: 10 | H15: 15 | I15: 20
B16: списания | C16: 0.04 | D16: 0 | F16: price | G16: =D18*100/G15 -> 420 | H16: =D18*100/H15 -> 280 | I16: =D18*100/I15 -> 210
B17: упаковка | C17: =D17/D18 -> 0 | D17: 0
B18: Итого с/с | D18: =SUM(D15:D17) -> 42
C22: Зал | D22: Доставка
B23: цена | C23: 190 | D23: =(C23/70)*100 -> 271.42857
B24: cost общий | C24: =D18/C23 -> 0.22105263
B25: cost - продукции | C25: =D15/C23 -> 0.22105263

Sheet Айран коктейль
A1: Наименование ТТК: | B1: Айран коктейль
A3: Ингредиент | B3: Брутто | C3: Нетто | D3: Ед.изм. | E3: вес потери | F3: % потери | G3: с/с руб. | H3: с/с % | I3: Выход (мл.)
A4: Айран турецкий 2% коктельный | B4: 200 | C4: =B4 -> 200 | D4: мл | E4: =B4-C4 -> 0 | F4: =E4/B4*100 -> 0 | G4: =VLOOKUP(A4,'Матрица поставщиков'!A1:E52,5,False) * B4 -> 47.5 | H4: =G4/G9 -> 0.74509804
A5: Сахарный сироп | B5: 10 | C5: =B5 -> 10 | D5: мл | E5: =B5-C5 -> 0 | F5: =E5/B5*100 -> 0 | G5: =VLOOKUP(A5,'Матрица поставщиков'!A1:E53,5,False) * B5 -> 3.35 | H5: =G5/G9 -> 0.05254902
A6: Концентрат сока | B6: 25 | C6: =B6 -> 25 | D6: мл | E6: =B6-C6 -> 0 | F6: =E6/B6*100 -> 0 | G6: =VLOOKUP(A6,'Матрица поставщиков'!A1:E57,5,False) * B6 -> 10 | H6: =G6/G9 -> 0.15686275
A7: Вода газированная | B7: 100 | C7: =B7 -> 100 | D7: мл | E7: =B7-C7 -> 0 | F7: =E7/B7*100 -> 0 | G7: =VLOOKUP(A7,'Матрица поставщиков'!A2:E58,5,False) * B7 -> 2.9 | H7: =G7/G9 -> 0.045490196
A8: Лёд куб | B8: 30 | C8: =B8 -> 30 | D8: г | E8: =B8-C8 -> 0 | F8: =E8/B8*100 -> 0 | G8: =VLOOKUP(A8,'Матрица поставщиков'!A3:E59,5,False) * B8 -> 0 | H8: =G8/G9 -> 0
A9: Итого | B9: =sum(B4:B8) -> 365 | C9: =SUM(C4:C8) -> 365 | D9: - | E9: =B9-C9 -> 0 | F9: =E9/B9*100 -> 0 | G9: =SUM(G4:G8) -> 63.75 | H9: =SUM(H4:H6) -> 0.9545098 | I9: =B9-E9 -> 365
A11: Технология приготовления
A12: 1. Смешать сахарный сироп с концентратом 2. Влить смесь в айран и взболтать 3. Добавить газированную воду 4. Добавить кубики льда 5. Смешать (не взбалтывать)
B14: выход | C14: с/с
B15: =I9 -> 365 | C15: =G9/I9*B15 -> 63.75
B16: 1 | C16: =G9/I9*B16 -> 0.17465753
B18: Для расчёта цены продажи
C19: % | D19: руб
B20: с/с блюда | C20: =D20/D23 -> 0.86971351 | D20: =C15 -> 63.75 | F20: cost (%) | G20: 15 | H20: 20 | I20: 22
B21: списания | C21: 0.04 | D21: =D20*C21 -> 2.55 | F21: price | G21: =D23*100/G20 -> 488.66667 | H21: =D23*100/H20 -> 366.5 | I21: =D23*100/I20 -> 333.18182
B22: упаковка | C22: =D22/D23 -> 0.095497954 | D22: 7
B23: Итого с/с | D23: =SUM(D20:D22) -> 73.3
B25: цена | C25: 290
B26: cost общий | C26: =D23/C25 -> 0.25275862
B27: cost - продукции | C27: =D20/C25 -> 0.21982759

Sheet Чай чёрный
A1: Наименование ТТК: | B1: Чай чёрный
A3: Ингредиент | B3: Брутто | C3: Нетто | D3: Ед.изм. | E3: вес потери | F3: % потери | G3: с/с руб. | H3: с/с % | I3: Выход (мл.)
A4: Чай чёрный турецкий | B4: 17.5 | C4: =B4 -> 17.5 | D4: г. | E4: =B4-C4 -> 0 | F4: =E4/B4*100 -> 0 | G4: =VLOOKUP(A4,'Матрица поставщиков'!A1:E60,5,False) * B4 -> 28.84 | H4: =G4/G6 -> 1
A5: вода | B5: 4800 | C5: =B5 -> 4800 | D5: г. | E5: =B5-C5 -> 0 | F5: =E5/B5*100 -> 0 | G5: =(VLOOKUP(A5,'Матрица поставщиков'!A1:E53,5,False) * B5)/10 -> 0 | H5: =G5/G6 -> 0
A6: Итого | B6: =B5 -> 4800 | C6: =B6 -> 4800 | D6: - | E6: =B6-C6 -> 0 | F6: =E6/B6*100 -> 0 | G6: =SUM(G4:G5) -> 28.84 | H6: =SUM(H4:H5) -> 1 | I6: =B6-E6 -> 4800
A8: Технология приготовления
A9: 1. Засыпать чай в чашку 2. Залить кипятком
B10: выход | C10: с/с
B11: 200 | C11: =G6/I6*B11 -> 1.2016667
B12: 1 | C12: =G6/I6*B12 -> 0.0060083333
B14: Для расчёта цены продажи
C15: % | D15: руб | E15: цена так
B16: с/с блюда | C16: =D16/D19 -> 0.14566127 | D16: =C11 -> 1.2016667 | F16: cost (%) | G16: 10 | H16: 15 | I16: 20
B17: списания | C17: 0.04 | D17: =D16*C17 -> 0.048066667 | F17: price | G17: =D19*100/G16 -> 82.497333 | H17: =D19*100/H16 -> 54.998222 | I17: =D19*100/I16 -> 41.248667
B18: упаковка | C18: =D18/D19 -> 0.84851228 | D18: 7
B19: Итого с/с | D19: =SUM(D16:D18) -> 8.2497333
B21: цена | C21: 150
B22: cost общий | C22: =D19/C21 -> 0.054998222
B23: cost - продукции | C23: =D16/C21 -> 0.0080111111

Sheet Манная халва с шоко
A1: Наименование ТТК: | B1: Манная халва с шоколадом
A3: Ингредиент | B3: Брутто | C3: Нетто | D3: Ед.изм. | E3: вес потери | F3: % потери | G3: с/с руб. | H3: с/с % | I3: Выход (мл.)
A4: п/ф Манная халва | B4: 150 | C4: 150 | D4: г. | E4: =B4-C4 -> 0 | F4: =E4/B4*100 -> 0 | G4: =B4*'пф Манная халва'!D23 -> 27.425819 | H4: =G4/G6 -> 0.79401252
A5: п/ф Топинг шоколадный | B5: 30 | C5: 30 | D5: г. | E5: =B5-C5 -> 0 | F5: =E5/B5*100 -> 0 | G5: =B5*'пф Топинг шоколадный'!D23 -> 7.1149701 | H5: =G5/$G$6 -> 0.20598748
A6: Итого | B6: =SUM(B4:B5) -> 180 | C6: =SUM(C4:C5) -> 180 | D6: г. | E6: =B6-C6 -> 0 | F6: =E6/B6*100 -> 0 | G6: =SUM(G4:G5) -> 34.540789 | H6: =SUM(H3:H5) -> 1 | I6: =C6 -> 180
A8: Технология приготовления
A9: Выложить в тару, шоколад сверху, подогреть в СВЧ 1.5 мин на средней мощности. Подать
B10: выход | C10: с/с
B11: 180 | C11: =G6/I6*B11 -> 34.540789
B12: 1 | C12: =G6/I6*B12 -> 0.19189327
B14: Для расчёта цены продажи
C15: % | D15: руб
B16: с/с блюда | C16: =D16/D19 -> 0.59449776 | D16: =C11 -> 34.540789 | F16: cost (%) | G16: 10 | H16: 15 | I16: 20
B17: списания | C17: 0 | D17: =D16*C17 -> 0 | F17: price | G17: =D19*100/G16 -> 581.00789 | H17: =D19*100/H16 -> 387.33859 | I17: =D19*100/I16 -> 290.50394
B18: упаковка | C18: =D18/D19 -> 0.40550224 | D18: =I29 -> 23.56
B19: Итого с/с | D19: =SUM(D16:D18) -> 58.100789 | G19: на месте | H19: с собой | I19: доставка
F20: списания | G20: 2 | H20: 2 | I20: 2
B21: цена | C21: 300 | F21: салфетки 4 шт. | G21: 1.2 | H21: 1.2 | I21: 1.2
B22: cost общий | C22: =I31/C21 -> 0.1936693 | F22: зубочистка | G22: 0.34 | H22: 0.34 | I22: 0.34
B23: cost - продукции | C23: =D16/C21 -> 0.11513596 | F23: пакет | G23: 0 | H23: 2 | I23: 2
F24: наклейка брендированная | G24: 2.5 | H24: 2.5 | I24: 2.5
B25: цена | C25: =C21 -> 300 | F25: Супница | G25: 12.85 | H25: 12.85 | I25: 12.85
B26: доставка | C26: 430 | F26: Ложка с упаковкой | G26: 2.67 | H26: 2.67 | I26: 2.67
G29: =SUM(G20:G28) -> 21.56 | H29: =SUM(H20:H28) -> 23.56 | I29: =SUM(I20:I28) -> 23.56
I31: =D16+I29 -> 58.100789

Sheet Кофе по-турецки
A1: Наименование ТТК: | B1: Кофе по-турецки
A3: Ингредиент | B3: Брутто | C3: Нетто | D3: Ед.изм. | E3: вес потери | F3: % потери | G3: с/с руб. | H3: с/с % | I3: Выход (мл.)
A4: Турецкий кофе KURUKAHVECI MEHMET EFENDI | B4: 10 | C4: 10 | D4: г. | E4: =B4-C4 -> 0 | F4: =E4/B4*100 -> 0 | G4: =VLOOKUP(A4,'Матрица поставщиков'!A1:E60,5,False) * B4 -> 13.04 | H4: =G4/G8 -> 0.50562233
A5: вода | B5: 100 | C5: 100 | D5: мл. | E5: =B5-C5 -> 0 | F5: =E5/B5*100 -> 0 | G5: =VLOOKUP(A5,'Матрица поставщиков'!A1:E53,5,False) * B5 -> 0 | H5: =G5/G8 -> 0
A6: Шоколадные камушки | B6: 5 | C6: 5 | D6: г. | E6: =B6-C6 -> 0 | F6: =E6/B6*100 -> 0 | G6: =VLOOKUP(A6,'Матрица поставщиков'!A2:E549,5,False) * B6 -> 7.5 | H6: =G6/G8 -> 0.29081039
A7: Лукум в шоколадке с мандарином | B7: 7 | C7: 7 | D7: г. | E7: =B7-C7 -> 0 | F7: =E7/B7*100 -> 0 | G7: =VLOOKUP(A7,'Матрица поставщиков'!A3:E559,5,False) * B7 -> 5.25 | H7: =G7/G8 -> 0.20356727
A8: Итого | B8: =B5 -> 100 | C8: =B8 -> 100 | D8: - | E8: =B8-C8 -> 0 | F8: =E8/B8*100 -> 0 | G8: =SUM(G4:G7) -> 25.79 | H8: =SUM(H4:H5) -> 0.50562233 | I8: =B8-E8 -> 100
A10: Технология приготовления
A11: Размешать кофе с холодной водой в турке, погрузить в песок, аккуратно покачивая. Как только начинает закипать, вытаскиваем, погружаем. повторяем 2 раза
B12: выход | C12: с/с
B13: 100 | C13: =G8/I8*B13 -> 25.79
B14: 1 | C14: =G8/I8*B14 -> 0.2579
B16: Для расчёта цены продажи
C17: % | D17: руб | E17: цена так
B18: с/с блюда | C18: =D18/D21 -> 0.894815 | D18: =C13 -> 25.79 | F18: cost (%) | G18: 5 | H18: 7 | I18: 9
B19: списания | C19: 0.04 | D19: =D18*C19 -> 1.0316 | F19: price | G19: =D21*100/G18 -> 576.432 | H19: =D21*100/H18 -> 411.73714 | I19: =D21*100/I18 -> 320.24
B20: упаковка | C20: =D20/D21 -> 0.0693924 | D20: 2
B21: Итого с/с | D21: =SUM(D18:D20) -> 28.8216
B23: цена | C23: 250 | E23: сахер у нас бесплатный
B24: cost общий | C24: =D21/C23 -> 0.1152864
B25: cost - продукции | C25: =D18/C23 -> 0.10316

Sheet Салеп
A1: Наименование ТТК: | B1: Салеп
A3: Ингредиент | B3: Брутто | C3: Нетто | D3: Ед.изм. | E3: вес потери | F3: % потери | G3: с/с руб. | H3: с/с % | I3: Выход (мл.)
A4: Салеп | B4: 20 | C4: =B4 -> 20 | D4: г. | E4: =B4-C4 -> 0 | F4: =E4/B4*100 -> 0 | G4: =VLOOKUP(A4,'Матрица поставщиков'!A1:E600,5,False) * B4 -> 34.7 | H4: =G4/G7 -> 0.74091472
A5: Молоко | B5: 200 | C5: 200 | D5: г. | E5: =B5-C5 -> 0 | F5: =E5/B5*100 -> 0 | G5: =(VLOOKUP(A5,'Матрица поставщиков'!A1:E53,5,FALSE) * B5) -> 12 | H5: =G5/G7 -> 0.25622411
A6: Корица | B6: 1 | C6: 1 | D6: г. | E6: =B6-C6 -> 0 | F6: =E6/B6*100 -> 0 | G6: =(VLOOKUP(A6,'Матрица поставщиков'!A2:E540,5,False) * B6)/10 -> 0.134 | H6: =G6/G7 -> 0.0028611692
A7: Итого | B7: =B5 -> 200 | C7: =B7 -> 200 | D7: - | E7: =B7-C7 -> 0 | F7: =E7/B7*100 -> 0 | G7: =SUM(G4:G6) -> 46.834 | H7: =SUM(H4:H6) -> 1 | I7: =B7-E7 -> 200
A9: Технология приготовления
A10: Смешать в стакане ложкой или размешивателем салеп с молоком до однородной массы. посыпать корицу
A11: выход | B11: с/с
A12: 200 | B12: =G7/I7*A12 -> 46.834
A13: 1 | B13: =G7/I7*A13 -> 0.23417
B15: % | C15: руб
A16: с/с блюда | B16: =C16/C19 -> 0.85608225 | C16: =B12 -> 46.834 | E16: cost (%) | F16: 5 | G16: 7 | H16: 9
A17: списания | B17: 0.04 | C17: =C16*B17 -> 1.87336 | E17: price | F17: =C19*100/F16 -> 1094.1472 | G17: =C19*100/G16 -> 781.53371 | H17: =C19*100/H16 -> 607.85956
A18: упаковка | B18: =C18/C19 -> 0.10967446 | C18: 6
A19: Итого с/с | C19: =SUM(C16:C18) -> 54.70736
A21: цена | B21: 250
A22: cost общий | B22: =C19/B21 -> 0.21882944
A23: cost - продукции | B23: =C16/B21 -> 0.187336

Sheet Чечевичный суп
A1: Наименование блюда: | B1: Чечевичный суп
A3: Ингредиент | B3: Брутто | C3: Нетто | D3: Ед.изм. | E3: Объём потери | F3: % потери | G3: с/с руб. | H3: с/с % | I3: Выход (мл.)
A4: п/ф Чечевичный суп | B4: 300 | C4: =B4 -> 300 | D4: г | E4: =B4-C4 -> 0 | F4: =E4/B4*100 -> 0 | G4: ='пф Чечевичный суп'!D21*B4 -> 17.385798 | H4: =G4/$G$6 -> 0.92202767
A5: п/ф Лимонная заправка | B5: 5 | C5: 5 | D5: г | E5: =B5-C5 -> 0 | F5: =E5/B5*100 -> 0 | G5: ='пф Лимонная заправка'!D11*B5 -> 1.47025 | H5: =G5/$G$6 -> 0.077972331
A6: Итого | B6: =SUM(B4:B5) -> 305 | C6: =SUM(C4:C5) -> 305 | D6: - | E6: =B6-C6 -> 0 | F6: - | G6: =SUM(G4:G5) -> 18.856048 | H6: =SUM(H4:H5) -> 1 | I6: =C6 -> 305
A8: Технология приготовления
A9: Налейте 300мл (3 половника) супа в супницу. Добавьте 5мл лимонно-папричной заправки обязательно предварительно взболтав! при заказе навынос закройте крышкой. Обязательно подайте ложку в пакете.
A11: Для расчёта цены продажи
A12: Состав позиции | B12: доля статьи % | C12: руб
A13: с/с блюда | B13: =C13/C20 -> 0.50212433 | C13: =F22 -> 18.546932 | E13: cost (%) | F13: 25 | G13: 26 | H13: 27 | I13: 27.75 | J13: 29 | K13: 30 | L13: 31
A14: списания | B14: =C14/C20 -> 0.054146348 | C14: 2 | E14: price | F14: =C20*100/F13 -> 147.74773 | G14: =C20*100/G13 -> 142.06512 | H14: =C20*100/H13 -> 136.80345 | I14: =C20*100/I13 -> 133.10606 | J14: =C20*100/J13 -> 127.36873 | K14: =C20*100/K13 -> 123.12311 | L14: =C20*100/L13 -> 119.15139
A15: салфетки 4 шт. | C15: 1.2
A16: зубочистка | B16: =C16/C20 -> 0.0092048792 | C16: 0.34
A17: пакет | B17: =C17/C20 -> 0.054146348 | C17: 2 | E17: 1гр | F17: =G6/I6 -> 0.061823107 | J17: на месте | K17: с собой | L17: доставка
A18: упаковка | B18: =C18/C20 -> 0.34789029 | C18: 12.85 | E18: 100гр | F18: =F17*100 -> 6.1823107 | I18: списания | J18: 2 | K18: 2 | L18: 2
A19: Ложка с упаковкой | B19: =C19/C20 -> 0.072285375 | C19: 2.67 | I19: салфетки 4 шт. | J19: 1.2 | K19: 1.2 | L19: 1.2
A20: Итого с/с | C20: =SUM(C13:C18) -> 36.936932 | E20: 200гр | F20: =F17*200 -> 12.364621 | I20: зубочистка | J20: 0.34 | K20: 0.34 | L20: 0.34
E21: 250гр | F21: =F17*250 -> 15.455777 | I21: пакет | J21: 0 | K21: 2 | L21: 2
A22: cost общий | B22: =L29/B24 -> 0.14035644 | E22: 300гр | F22: =F17*300 -> 18.546932 | I22: наклейка брендированная | J22: 2.5 | K22: 2.5 | L22: 2.5
A23: cost - продукции | B23: =C13/B24 -> 0.061823107 | I23: Супница | J23: 12.85 | K23: 12.85 | L23: 12.85
A24: Цена | B24: 300 | C24: =B24+L27 -> 323.56 | I24: Ложка с упаковкой | J24: 2.67 | K24: 2.67 | L24: 2.67
A26: цена | B26: =B24 -> 300
A27: для доставки | B27: 430 | J27: =SUM(J18:J26) -> 21.56 | K27: =SUM(K18:K26) -> 23.56 | L27: =SUM(L18:L26) -> 23.56
I29: с/с продукции + с/с упаковки | L29: =C13+L27 -> 42.106932

Sheet КОМБО ЛАЙТ - 1
A1: Наименование позиции: | B1: Комбо ЛАЙТ
A3: Ингредиент | B3: Брутто | C3: Нетто | D3: Ед.изм. | E3: с/с руб. | F3: с/с % | G3: Выход (мл.)
A4: ='Дюрюм mini'!B1 -> Дюрюм mini | B4: ='Дюрюм mini'!B11 -> 295 | C4: ='Дюрюм mini'!C11 -> 220 | D4: г | E4: ='Дюрюм mini'!G11 -> 62.066495 | F4: =E4/$E$9 -> 0.56562347
A5: ='Чечевичный суп'!B1 -> Чечевичный суп | B5: 200 | C5: 200 | D5: г | E5: ='Чечевичный суп'!F17*C5 -> 12.364621 | F5: =E5/$E$9 -> 0.11268109
A6: Упаковка для дюрюма | B6: - | C6: - | D6: - | E6: =SUM('Дюрюм mini'!C19:C25)-E8 -> 14.24 | F6: =E6/$E$9 -> 0.12977176
A7: Упаковка для супа | B7: - | C7: - | D7: - | E7: =SUM('Чечевичный суп'!C14:C19)-E8 -> 19.06 | F7: =E7/$E$9 -> 0.17369731
A8: пакет | B8: - | C8: - | D8: - | E8: =2 -> 2 | F8: =E8/$E$9 -> 0.018226371
A9: Итого | B9: =SUM(B4:B5) -> 495 | C9: =SUM(C4:C5) -> 420 | D9: - | E9: =SUM(E4:E8) -> 109.73112 | F9: =SUM(F4:F5) -> 0.67830456 | G9: =C9 -> 420
A14: Наименование | B14: cost % | C14: руб.
A15: TOTAL COST | B15: =B16+B17 -> 0.22394105
A16: PACKAGE COST | B16: =SUM(E6:E8)/C18 -> 0.072040816
A17: FOOD COST | B17: =SUM(E4:E5)/C18 -> 0.15190024
A18: Цена | C18: 490
A19: Цена в доставку (recommend) | C19: =C18/0.7 -> 700

Sheet КОМБО ОБЕД - 1
A1: Наименование позиции: | B1: Комбо ОБЕД
A3: Ингредиент | B3: Брутто | C3: Нетто | D3: Ед.изм. | E3: с/с руб. | F3: с/с % | G3: Выход (мл.)
A4: ='Дюрюм mini'!B1 -> Дюрюм mini | B4: ='Дюрюм mini'!B11 -> 295 | C4: ='Дюрюм mini'!C11 -> 220 | D4: г | E4: ='Дюрюм mini'!G11 -> 62.066495 | F4: =E4/$E$14 -> 0.27142018
A5: ='Чечевичный суп'!B1 -> Чечевичный суп | B5: 200 | C5: 200 | D5: г | E5: ='Чечевичный суп'!F17*C5 -> 12.364621 | F5: =E5/$E$14 -> 0.054071167
A6: Кола | B6: 330 | C6: 330 | D6: мл | E6: 55 | F6: =E6/$E$14 -> 0.24051801
A7: Фри | B7: 100 | C7: 100 | D7: г | E7: ='Фри на продажу'!C14*C7 -> 33.452985 | F7: =E7/$E$14 -> 0.14629174
A8: Соус | B8: ='Сырный соус'!B10 -> 30 | C8: 30 | D8: г | E8: ='Сырный соус'!C10 -> 15.469 | F8: =E8/$E$14 -> 0.067646784
A9: Упаковка для дюрюма | B9: - | C9: - | D9: - | E9: =SUM('Дюрюм mini'!C19:C25)-E13 -> 14.24 | F9: =E9/$E$14 -> 0.0622723
A10: Упаковка для супа | B10: - | C10: - | D10: - | E10: =SUM('Чечевичный суп'!C14:C19)-E13 -> 19.06 | F10: =E10/$E$14 -> 0.083350424
A11: Упаковка для соуса | B11: - | C11: - | D11: - | E11: ='Сырный соус'!J31 -> 4.76 | F11: =E11/$E$14 -> 0.020815741
A12: Упаковка для фри | B12: - | C12: - | D12: - | E12: ='Фри на продажу'!J34 -> 10.26 | F12: =E12/$E$14 -> 0.044867542
A13: пакет | B13: - | C13: - | D13: - | E13: =2 -> 2 | F13: =E13/$E$14 -> 0.0087461096
A14: Итого | B14: =SUM(B4:B13) -> 955 | C14: =SUM(C4:C13) -> 880 | D14: - | E14: =SUM(E4:E13) -> 228.6731 | F14: =SUM(F4:F5) -> 0.32549135 | G14: =C14 -> 880
A19: Наименование | B19: cost % | C19: руб.
A20: TOTAL COST | B20: =B21+B22 -> 0.30489747
A21: PACKAGE COST | B21: =SUM(E9:E13)/C23 -> 0.067093333
A22: FOOD COST | B22: =SUM(E4:E8)/C23 -> 0.23780414
A23: Цена | C23: 750
A24: Цена в доставку (recommend) | C24: =C23/0.7 -> 1071.4286

Sheet КОМБО ЛАЙТ - 2
A1: Наименование позиции: | B1: Комбо ЛАЙТ
A3: Ингредиент | B3: Брутто | C3: Нетто | D3: Ед.изм. | E3: с/с руб. | F3: с/с % | G3: Выход (мл.)
A4: ='Дюрюм'!B1 -> Дюрюм | B4: ='Дюрюм'!B11 -> 435 | C4: ='Дюрюм'!C11 -> 342 | D4: г | E4: ='Дюрюм'!G11 -> 100.31737 | F4: =E4/$E$9 -> 0.67790255
A5: ='Чечевичный суп'!B1 -> Чечевичный суп | B5: 200 | C5: 200 | D5: г | E5: ='Чечевичный суп'!F17*C5 -> 12.364621 | F5: =E5/$E$9 -> 0.083554908
A6: Упаковка для дюрюма | B6: - | C6: - | D6: - | E6: =SUM('Дюрюм'!C19:C25)-E8 -> 14.24 | F6: =E6/$E$9 -> 0.096227927
A7: Упаковка для супа | B7: - | C7: - | D7: - | E7: =SUM('Чечевичный суп'!C14:C19)-E8 -> 19.06 | F7: =E7/$E$9 -> 0.12879946
A8: пакет | B8: - | C8: - | D8: - | E8: =2 -> 2 | F8: =E8/$E$9 -> 0.013515158
A9: Итого | B9: =SUM(B4:B5) -> 635 | C9: =SUM(C4:C5) -> 542 | D9: - | E9: =SUM(E4:E8) -> 147.98199 | F9: =SUM(F4:F5) -> 0.76145746 | G9: =C9 -> 542
A14: Наименование | B14: cost % | C14: руб.
A15: TOTAL COST | B15: =B16+B17 -> 0.25081693
A16: PACAGE COST | B16: =SUM(E6:E8)/C18 -> 0.059830508
A17: FOOD COST | B17: =SUM(E4:E5)/C18 -> 0.19098642
A18: Цена | C18: 590
A19: Цена в доставку (recommend) | C19: =C18/0.7 -> 842.85714

Sheet КОМБО ОБЕД - 2
A1: Наименование позиции: | B1: Комбо ОБЕД
A3: Ингредиент | B3: Брутто | C3: Нетто | D3: Ед.изм. | E3: с/с руб. | F3: с/с % | G3: Выход (мл.)
A4: ='Дюрюм'!B1 -> Дюрюм | B4: ='Дюрюм'!B11 -> 435 | C4: ='Дюрюм'!C11 -> 342 | D4: г | E4: ='Дюрюм'!G11 -> 100.31737 | F4: =E4/E14 -> 0.37582749
A5: ='Чечевичный суп'!B1 -> Чечевичный суп | B5: 200 | C5: 200 | D5: г | E5: ='Чечевичный суп'!F17*C5 -> 12.364621 | F5: =E5/$E$14 -> 0.046322634
A6: Кола | B6: 330 | C6: 330 | D6: мл | E6: 55 | F6: =E6/$E$14 -> 0.20605118
A7: Фри | B7: 100 | C7: 100 | D7: г | E7: ='Фри на продажу'!C14*C7 -> 33.452985 | F7: =E7/$E$14 -> 0.12532777
A8: Соус | B8: ='Сырный соус'!B10 -> 30 | C8: 30 | D8: г | E8: ='Сырный соус'!C10 -> 15.469 | F8: =E8/$E$14 -> 0.057952831
A9: Упаковка для дюрюма | B9: - | C9: - | D9: - | E9: =SUM('Дюрюм mini'!C19:C25)-E13 -> 14.24 | F9: =E9/$E$14 -> 0.053348524
A10: Упаковка для супа | B10: - | C10: - | D10: - | E10: =SUM('Чечевичный суп'!C14:C19)-E13 -> 19.06 | F10: =E10/$E$14 -> 0.0714061
A11: Упаковка для соуса | B11: - | C11: - | D11: - | E11: ='Сырный соус'!J31 -> 4.76 | F11: =E11/$E$14 -> 0.017832793
A12: Упаковка для фри | B12: - | C12: - | D12: - | E12: ='Фри на продажу'!J34 -> 10.26 | F12: =E12/$E$14 -> 0.038437911
A13: пакет | B13: - | C13: - | D13: - | E13: =2 -> 2 | F13: =E13/$E$14 -> 0.0074927702
A14: Итого | B14: =SUM(B4:B5) -> 635 | C14: =SUM(C4:C5) -> 542 | D14: - | E14: =SUM(E4:E13) -> 266.92397 | F14: =SUM(F4:F5) -> 0.42215012 | G14: =C14 -> 542
A19: Наименование | B19: cost % | C19: руб.
A20: TOTAL COST | B20: =B21+B22 -> 0.2809726
A21: PACAGE COST | B21: =SUM(E9:E13)/C23 -> 0.052968421
A22: FOOD COST | B22: =SUM(E4:E8)/C23 -> 0.22800418
A23: Цена | C23: 950
A24: Цена в доставку (recommend) | C24: =C23/0.7 -> 1357.1429

Sheet Искенди кебаб
A1: Наименование блюда: | B1: Кебаб Искенди
A3: Ингредиент | B3: Брутто | C3: Нетто | D3: Ед.изм. | E3: Объём потери | F3: % потери | G3: с/с руб. | H3: с/с % | I3: Выход (мл.)
A4: п/ф Фарш Primebeef Классик жареный | B4: 100 | C4: =B4 -> 100 | D4: г | E4: =B4-C4 -> 0 | F4: =E4/B4*100 -> 0 | G4: ='пф Фарш Primebeef Классик жарен'!D14*B4 -> 145.86927 | H4: =G4/$G$8 -> 0.92332301
A5: п/ф Лаваш Искенди | B5: 0.25 | C5: 0.25 | D5: шт. | E5: =B5-C5 -> 0 | F5: =E5/B5*100 -> 0 | G5: ='пф Лаваш Искенди'!G6*B5 -> 4.70986 | H5: =G5/$G$8 -> 0.029812463
A6: п/ф Соус Кебаб | B6: 40 | C6: 40 | D6: г | E6: =B6-C6 -> 0 | F6: =E6/B6*100 -> 0 | G6: ='пф Соус Кебаб'!D21*B6 -> 3.3493946 | H6: =G6/G8 -> 0.021200992
A7: п/ф Лук маринованный | B7: 30 | C7: 30 | D7: г | E7: =B7-C7 -> 0 | F7: =E7/B7*100 -> 0 | G7: ='пф Лук маринованный'!D18*B7 -> 4.0544 | H7: =G7/G8 -> 0.025663534
A8: Итого | B8: =SUM(B4:B7) -> 170.25 | C8: =SUM(C4:C7) -> 170.25 | D8: - | E8: =B8-C8 -> 0 | F8: - | G8: =SUM(G4:G7) -> 157.98292 | H8: =SUM(H4:H7) -> 1 | I8: =B8-E8 -> 170.25
A10: Технология приготовления
A11: Подача: на половине половины лаваша(П/Ф), соус кебаб 40гр, лук Маринованный пф 30гр
A13: Для расчёта цены продажи
A14: Состав позиции | B14: доля статьи % | C14: руб
A15: с/с блюда | B15: =C15/C21 -> 0.91945196 | C15: =G8 -> 157.98292 | E15: cost (%) | F15: 25 | G15: 26 | H15: 27 | I15: 27.75 | J15: 29 | K15: 30 | L15: 31
A16: списания | B16: =C16/C21 -> 0.011639891 | C16: 2 | E16: price | F16: =C21*100/F15 -> 687.29168 | G16: =C21*100/G15 -> 660.85739 | H16: =C21*100/H15 -> 636.38119 | I16: =C21*100/I15 -> 619.1817 | J16: =C21*100/J15 -> 592.49283 | K16: =C21*100/K15 -> 572.74307 | L16: =C21*100/L15 -> 554.26749
A17: салфетки 4 шт. | B17: =C17/C21 -> 0.023279781 | C17: 4
A18: зубочистка | B18: =C18/C21 -> 0.0019787814 | C18: 0.34
A19: пакет | B19: =C19/C21 -> 0.011639891 | C19: 2
A20: упаковка | B20: =C20/C21 -> 0.032009699 | C20: 5.5
A21: Итого с/с | C21: =SUM(C15:C20) -> 171.82292
F22: на месте | G22: с собой | H22: доставка
A23: cost общий | B23: =H34/B25 -> 0.26397525 | E23: списания | F23: 2 | G23: 2 | H23: 2
A24: cost - продукции | B24: =G8/B25 -> 0.22896075 | E24: салфетки 4 шт. | F24: 1.2 | G24: 1.2 | H24: 1.2
A25: Цена | B25: 690 | C25: =B25+H32 -> 714.16 | E25: зубочистка | F25: 0.34 | G25: 0.34 | H25: 0.34
E26: пакет | F26: 0 | G26: 2 | H26: 2
E27: наклейка брендированная | F27: 0 | G27: 2.5 | H27: 2.5
A28: цена | B28: 575 | E28: Алюм контейнер | F28: 10 | G28: 10 | H28: 10
A29: доставка | B29: 820 | E29: крышка | F29: 0 | G29: 2.32 | H29: 2.32
E30: Соусник | F30: 3.8 | G30: 3.8 | H30: 3.8
F32: =SUM(F23:F31) -> 17.34 | G32: =SUM(G23:G31) -> 24.16 | H32: =SUM(H23:H31) -> 24.16
G34: с/с | H34: =C15+H32 -> 182.14292

Sheet Дюрюм mini
A1: Наименование блюда: | B1: Дюрюм mini
A3: Ингредиент | B3: Брутто | C3: Нетто | D3: Ед.изм. | E3: Объём потери | F3: % потери | G3: с/с руб. | H3: с/с % | I3: Выход (мл.)
A4: п/ф курица жареная | B4: 50 | C4: 50 | D4: г | E4: =B4-C4 -> 0 | F4: =E4/B4*100 -> 0 | G4: ='пф курица готовая'!G6/'пф курица готовая'!I6*B4 -> 25.709425 | H4: =G4/$G$11 -> 0.4142239
A5: п/ф Лаваш Искенди 1/2 | B5: 50 | C5: 50 | D5: г | E5: 0 | F5: =E5/B5*100 -> 0 | G5: ='пф Лаваш Искенди'!G6/2 -> 9.41972 | H5: =G5/$G$11 -> 0.1517682
A6: Помидоры - сливовые | B6: 20 | C6: 20 | D6: г | E6: =B6-C6 -> 0 | F6: =E6/B6*100 -> 0 | G6: =VLOOKUP(A6,'Матрица поставщиков'!A1:E53,5,0) * B6 -> 7 | H6: =G6/G11 -> 0.11278227
A7: п/ф искандер соус | B7: 120 | C7: 45 | D7: мл | E7: =B7-C7 -> 75 | F7: =E7/B7*100 -> 62.5 | G7: =('пф искандер соус'!G11/'пф искандер соус'!I11)*B7 -> 4.33944 | H7: =G7/$G$11 -> 0.069915983
A8: Маринованные огурцы (целые) | B8: 20 | C8: 20 | D8: г | E8: =B8-C8 -> 0 | F8: =E8/B8*100 -> 0 | G8: =VLOOKUP(A8,'Матрица поставщиков'!A1:E507,5,0) * B8 -> 7.2933333 | H8: =G8/$G$11 -> 0.11750838
A9: Йогурт | B9: 20 | C9: =B9 -> 20 | D9: г | E9: =B9-C9 -> 0 | F9: =E9/B9*100 -> 0 | G9: =VLOOKUP(A9,'Матрица поставщиков'!A1:E503,5,0) * B9 -> 3.5266667 | H9: =G9/$G$11 -> 0.05682078
A10: п/ф Фри | B10: 15 | C10: 15 | D10: г | E10: =B10-C10 -> 0 | F10: =E10/B10*100 -> 0 | G10: =('пф Фри'!G7/'пф Фри'!I7) * B10 -> 4.7779095 | H10: =G10/$G$11 -> 0.076980495
A11: Итого | B11: =SUM(B4:B10) -> 295 | C11: =SUM(C4:C10) -> 220 | D11: - | E11: =B11-C11 -> 75 | F11: - | G11: =SUM(G4:G10) -> 62.066495 | H11: =SUM(H4:H10) -> 1 | I11: =B11-E11 -> 220
A13: Технология приготовления
A14: 1. Разогреть гриль до 200 4. Разместить один лаваш поверх другого симметрично 5. Выложить дорожкой по центру маринованные огурцы 6. Выложить дорожкой по центру помидоры нарезанные 7. Выложить дорожкой по центру мясо 8. Разместить по центру белый соус и Искенди 9. Завернуть лаваш 10. полить гриль полоской 20 гр соуса и поджарить 30 секунд до слегка тёмной корочки *в 10-м пункте начинать жарить со стороны открытого лаваша ( нужно запечатать )
A16: Для расчёта цены продажи
A17: Состав позиции | B17: доля статьи % | C17: руб | E17: cost (%) | F17: 25 | G17: 26 | H17: 27 | I17: 27.75 | J17: 29 | K17: 30 | L17: 31
A18: с/с блюда | B18: =C18/C26 -> 0.84551776 | C18: =G11 -> 62.066495 | E18: price | F18: =C26*100/F17 -> 293.62598 | G18: =C26*100/G17 -> 282.33267 | H18: =C26*100/H17 -> 271.87591 | I18: =C26*100/I17 -> 264.52791 | J18: =C26*100/J17 -> 253.12584 | K18: =C26*100/K17 -> 244.68832 | L18: =C26*100/L17 -> 236.79514
A19: списания | B19: =C19/C26 -> 0.027245546 | C19: 2
A20: салфетки 2 шт. | B20: =C20/C26 -> 0.0081736637 | C20: 0.6 | F20: на месте | G20: с собой | H20: доставка
A21: зубочистка | B21: =C21/C26 -> 0.0046317427 | C21: 0.34 | E21: списания | F21: 2 | G21: 2 | H21: 2
A22: пакет | B22: =C22/$C$26 -> 0.027245546 | C22: 2 | E22: салфетки 2 шт. | F22: 0.6 | G22: 0.6 | H22: 0.6
A23: наклейка брендированная | B23: =C23/$C$26 -> 0.021796436 | C23: 1.6 | E23: зубочистка | F23: 0.34 | G23: 0.34 | H23: 0.34
A24: Гриль пакет | B24: =C24/C26 -> 0.092634855 | C24: 6.8 | E24: пакет | F24: 0 | G24: 2 | H24: 2
A25: Фольга | B25: =C25/$C$26 -> 0.039506041 | C25: 2.9 | E25: наклейка брендированная | F25: 1.6 | G25: 1.6 | H25: 1.6
A26: Итого с/с | C26: =C18+F28 -> 73.406495 | E26: Гриль пакет | F26: 6.8 | G26: 6.8 | H26: 6.8
E27: Фольга | F27: 0 | G27: 2.9 | H27: 2.9
E28: Итого | F28: =SUM(F21:F27) -> 11.34 | G28: =SUM(G21:G27) -> 16.24 | H28: =SUM(H21:H27) -> 16.24
A29: Наименование | B29: cost % | C29: руб.
A30: TOTAL COST | B30: =C26/C33 -> 0.20973284
A31: PACKAGE COST | B31: =F28/C33 -> 0.0324
A32: FOOD COST | B32: =C18/C33 -> 0.17733284
A33: Цена | C33: 350
A34: Цена в доставку | C34: =C33/0.7 -> 500

Sheet Дюрюм
A1: Наименование блюда: | B1: Дюрюм
A3: Ингредиент | B3: Брутто | C3: Нетто | D3: Ед.изм. | E3: Объём потери | F3: % потери | G3: с/с руб. | H3: с/с % | I3: Выход (мл.)
A4: п/ф курица жареная | B4: 83 | C4: =B4 -> 83 | D4: г | E4: =B4-C4 -> 0 | F4: =E4/B4*100 -> 0 | G4: ='пф курица готовая'!G6/'пф курица готовая'!I6*B4 -> 42.677646 | H4: =G4/$G$11 -> 0.4254263
A5: п/ф Лаваш Искенди | B5: 100 | C5: 100 | D5: г | E5: 0 | F5: =E5/B5*100 -> 0 | G5: ='пф Лаваш Искенди'!G6 -> 18.83944 | H5: =G5/$G$11 -> 0.18779839
A6: Помидоры - сливовые | B6: 30 | C6: 30 | D6: г | E6: =B6-C6 -> 0 | F6: =E6/B6*100 -> 0 | G6: =VLOOKUP(A6,'Матрица поставщиков'!A1:E53,5,0) * B6 -> 10.5 | H6: =G6/G11 -> 0.10466782
A7: п/ф искандер соус | B7: 140 | C7: 52 | D7: мл | E7: =B7-C7 -> 88 | F7: =E7/B7*100 -> 62.857143 | G7: =('пф искандер соус'!G11/'пф искандер соус'!I11)*B7 -> 5.06268 | H7: =G7/$G$11 -> 0.050466636
A8: Маринованные огурцы (целые) | B8: 30 | C8: 30 | D8: г | E8: =B8-C8 -> 0 | F8: =E8/B8*100 -> 0 | G8: =VLOOKUP(A8,'Матрица поставщиков'!A1:E57,5,0) * B8 -> 10.94 | H8: =G8/$G$11 -> 0.1090539
A9: Йогурт | B9: 30 | C9: 25 | D9: г | E9: =B9-C9 -> 5 | F9: =E9/B9*100 -> 16.666667 | G9: =VLOOKUP(A9,'Матрица поставщиков'!A1:E530,5,0) * B9 -> 5.29 | H9: =G9/$G$11 -> 0.052732644
A10: п/ф Фри | B10: 22 | C10: 22 | D10: г | E10: =B10-C10 -> 0 | F10: =E10/B10*100 -> 0 | G10: =('пф Фри'!G7/'пф Фри'!I7) * B10 -> 7.0076006 | H10: =G10/$G$11 -> 0.069854312
A11: Итого | B11: =SUM(B4:B10) -> 435 | C11: =SUM(C4:C10) -> 342 | D11: - | E11: =B11-C11 -> 93 | F11: - | G11: =SUM(G4:G10) -> 100.31737 | H11: =SUM(H4:H10) -> 1 | I11: =B11-E11 -> 342
A13: Технология приготовления
